/usr/local/lib/python3.8/dist-packages/telegram/ext/conversationhandler.py:287: UserWarning: If 'per_message=False', 'CallbackQueryHandler' will not be tracked for every message.
  warnings.warn(
No error handlers are registered, logging exception.
Traceback (most recent call last):
  File "/usr/local/lib/python3.8/dist-packages/telegram/ext/dispatcher.py", line 555, in process_update
    handler.handle_update(update, self, check, context)
  File "/usr/local/lib/python3.8/dist-packages/telegram/ext/conversationhandler.py", line 626, in handle_update
    new_state = handler.handle_update(update, dispatcher, check_result, context)
  File "/usr/local/lib/python3.8/dist-packages/telegram/ext/handler.py", line 198, in handle_update
    return self.callback(update, context)
  File "main.py", line 60, in save_surname
    data[update.effective_user.id]["surname"] = update.message.text
AttributeError: 'NoneType' object has no attribute 'text'
No error handlers are registered, logging exception.
Traceback (most recent call last):
  File "/usr/local/lib/python3.8/dist-packages/telegram/ext/dispatcher.py", line 555, in process_update
    handler.handle_update(update, self, check, context)
  File "/usr/local/lib/python3.8/dist-packages/telegram/ext/conversationhandler.py", line 626, in handle_update
    new_state = handler.handle_update(update, dispatcher, check_result, context)
  File "/usr/local/lib/python3.8/dist-packages/telegram/ext/handler.py", line 198, in handle_update
    return self.callback(update, context)
  File "main.py", line 95, in save_skills
    db_handler.save(list(data[update.effective_user.id].items()), "volunteers")
  File "/root/assistenza-ucraina-pisa-bot/db/db.py", line 19, in save
    self.cur.execute(f"insert into {table} ({','.join(cols)}) values " + marks, vals)
sqlite3.IntegrityError: NOT NULL constraint failed: volunteers.username
No error handlers are registered, logging exception.
Traceback (most recent call last):
  File "/usr/local/lib/python3.8/dist-packages/telegram/ext/dispatcher.py", line 555, in process_update
    handler.handle_update(update, self, check, context)
  File "/usr/local/lib/python3.8/dist-packages/telegram/ext/conversationhandler.py", line 626, in handle_update
    new_state = handler.handle_update(update, dispatcher, check_result, context)
  File "/usr/local/lib/python3.8/dist-packages/telegram/ext/handler.py", line 198, in handle_update
    return self.callback(update, context)
  File "main.py", line 95, in save_skills
    db_handler.save(list(data[update.effective_user.id].items()), "volunteers")
  File "/root/assistenza-ucraina-pisa-bot/db/db.py", line 19, in save
    self.cur.execute(f"insert into {table} ({','.join(cols)}) values " + marks, vals)
sqlite3.IntegrityError: NOT NULL constraint failed: volunteers.username
No error handlers are registered, logging exception.
Traceback (most recent call last):
  File "/usr/local/lib/python3.8/dist-packages/telegram/ext/dispatcher.py", line 555, in process_update
    handler.handle_update(update, self, check, context)
  File "/usr/local/lib/python3.8/dist-packages/telegram/ext/conversationhandler.py", line 626, in handle_update
    new_state = handler.handle_update(update, dispatcher, check_result, context)
  File "/usr/local/lib/python3.8/dist-packages/telegram/ext/handler.py", line 198, in handle_update
    return self.callback(update, context)
  File "main.py", line 95, in save_skills
    db_handler.save(list(data[update.effective_user.id].items()), "volunteers")
  File "/root/assistenza-ucraina-pisa-bot/db/db.py", line 19, in save
    self.cur.execute(f"insert into {table} ({','.join(cols)}) values " + marks, vals)
sqlite3.IntegrityError: NOT NULL constraint failed: volunteers.username
/usr/local/lib/python3.8/dist-packages/telegram/ext/conversationhandler.py:287: UserWarning: If 'per_message=False', 'CallbackQueryHandler' will not be tracked for every message.
  warnings.warn(
